Workbook

Sheet PVC
A1: No. | B1: Deskripsi | C1: Nilai | D1: Satuan | E1: Keliling
A2: 1 | B2: 'tolerance | C2: 0.2 | D2: mm
A3: 2 | B3: 1/2 OD | C3: 22 | D3: mm | E3: =(PI()*C3^2)/4 -> 380.13271
A4: 3 | B4: 1/2 Thick | C4: 1.5 | D4: mm
A5: 4 | B5: 1/2 ID | C5: =C3-2*C4 -> 19 | D5: mm | E5: =(PI()*C5^2)/4 -> 283.52874
A6: 5 | B6: 3/4 OD | C6: 26 | D6: mm | E6: =(PI()*C6^2)/4 -> 530.92916
A7: 6 | B7: 3/4 Thick | C7: 1.8 | D7: mm
A8: 7 | B8: 3/4 ID | C8: =C6-2*C7 -> 22.4 | D8: mm | E8: =(PI()*C8^2)/4 -> 394.08138
A9: 8 | B9: 1 OD | C9: 32 | D9: mm | E9: =(PI()*C9^2)/4 -> 804.24772
A10: 9 | B10: 1 Thick | C10: 2 | D10: mm
A11: 10 | B11: 1 ID | C11: =C9-2*C10 -> 28 | D11: mm | E11: =(PI()*C11^2)/4 -> 615.75216
A12: 11 | B12: 1 1/4 OD | C12: 42 | D12: mm | E12: =(PI()*C12^2)/4 -> 1385.4424
A13: 12 | B13: 1 1/4 Thick | C13: 2.3 | D13: mm
A14: 13 | B14: 1 1/4 ID | C14: =C12-2*C13 -> 37.4 | D14: mm | E14: =(PI()*C14^2)/4 -> 1098.5835
A15: 14 | B15: 1 1/2 OD | C15: 48 | D15: mm | E15: =(PI()*C15^2)/4 -> 1809.5574
A16: 15 | B16: 1 1/2 Thick | C16: 2.3 | D16: mm
A17: 16 | B17: 1 1/2 ID | C17: =C15-2*C16 -> 43.4 | D17: mm | E17: =(PI()*C17^2)/4 -> 1479.3446
A18: 17 | B18: 2 OD | C18: 60 | D18: mm | E18: =(PI()*C18^2)/4 -> 2827.4334
A19: 18 | B19: 2 Thick | C19: 2.3 | D19: mm
A20: 19 | B20: 2 ID | C20: =C18-2*C19 -> 55.4 | D20: mm | E20: =(PI()*C20^2)/4 -> 2410.5126
A21: 20 | B21: 2 1/2 OD | C21: 76 | D21: mm | E21: =(PI()*C21^2)/4 -> 4536.4598
A22: 21 | B22: 2 1/2 Thick | C22: 2.6 | D22: mm
A23: 22 | B23: 2 1/2 ID | C23: =C21-2*C22 -> 70.8 | D23: mm | E23: =(PI()*C23^2)/4 -> 3936.9182
A24: 23 | B24: 3 OD | C24: 89 | D24: mm | E24: =(PI()*C24^2)/4 -> 6221.1389
A25: 24 | B25: 3 Thick | C25: 3.1 | D25: mm
A26: 25 | B26: 3 ID | C26: =C24-2*C25 -> 82.8 | D26: mm | E26: =(PI()*C26^2)/4 -> 5384.5641
A27: 26 | B27: 4 OD | C27: 114 | D27: mm | E27: =(PI()*C27^2)/4 -> 10207.035
A28: 27 | B28: 4 Thick | C28: 4.1 | D28: mm
A29: 28 | B29: 4 ID | C29: =C27-2*C28 -> 105.8 | D29: mm | E29: =(PI()*C29^2)/4 -> 8791.4643
A30: 29 | B30: 'capHight | C30: 33.5 | D30: mm
F31: Jarak
B32: Lifting Tube OD | C32: =C12 -> 42 | D32: mm | E32: =E12 -> 1385.4424 | F32: =E32/'airlift-model'!G54 -> 55.417694
B33: Diffuser shell ID | C33: =C20 -> 55.4 | D33: mm
B34: Collar | C34: =(C33-C32)/2 -> 6.7 | D34: mm

Sheet airlift-model
A1: No | B1: Jenis | C1: Parameter | D1: Simbol | E1: Satuan | F1: Nilai_atau_Formula_Excel | G1: Column1 | H1: Column2 | I1: Column22 | J1: Column3 | K1: Rumus_Umum | L1: Keterangan
F2: 3" | G2: 1 1/4" | H2: 1" | I2: 3/4" | J2: 1/2"
A3: 1 | B3: Input | C3: Diameter kolam | D3: D_tank | E3: m | F3: 2 | G3: 1 | H3: 1 | I3: 1 | J3: 1 | L3: Diameter kolam Gambiran
A4: 2 | B4: Perhitungan | C4: Radius kolam | D4: R_tank | E4: m | F4: =F3/2 -> 1 | G4: =G3/2 -> 0.5 | H4: =H3/2 -> 0.5 | I4: =I3/2 -> 0.5 | J4: =J3/2 -> 0.5 | K4: D/2 | L4: Radius kolam
A5: 3 | B5: Input | C5: Kedalaman air | D5: H_water | E5: m | F5: 0.74 | G5: 0.65 | H5: 0.65 | I5: 0.74 | J5: 0.74 | L5: Kedalaman aktual kolam
A6: 4 | B6: Perhitungan | C6: Volume kolam | D6: V_tank | E6: m3 | F6: =PI()*F4^2*F5 -> 2.3247786 | G6: =PI()*G4^2*G5 -> 0.51050881 | H6: =PI()*H4^2*H5 -> 0.51050881 | I6: =PI()*I4^2*I5 -> 0.58119464 | J6: =PI()*J4^2*J5 -> 0.58119464 | K6: pi*r^2*h | L6: Volume efektif kolam
A7: 5 | B7: Input | C7: Diameter dalam lift tube | D7: D_tube | E7: m | F7: 0.076 | G7: =(PVC!C12-2*PVC!C13)/1000 -> 0.0374 | H7: =(PVC!C9-2*PVC!C10)/1000 -> 0.028 | I7: =(PVC!C6-2*PVC!C7)/1000 -> 0.0224 | J7: =(PVC!C5-2*PVC!C4)/1000 -> 0.016 | L7: ID lift tube 76 mm
A8: 6 | B8: Input | C8: Total flow path | D8: L_total | E8: m | F8: 1 | G8: 1 | H8: 1 | I8: 1 | J8: 1 | L8: Total panjang lift tube + discharge pipe
A9: 7 | B9: Input | C9: Kedalaman injeksi | D9: h_inj | E9: m | F9: 0.65 | G9: 0.6 | H9: 0.6 | I9: 0.65 | J9: 0.65 | L9: Kedalaman diffuser dari permukaan/outlet
A10: 8 | B10: Input | C10: Outlet depth | D10: h_out | E10: m | F10: 0.05 | G10: 0.05 | H10: 0.05 | I10: 0.05 | J10: 0.05 | L10: Outlet 50 mm di bawah permukaan
A11: 9 | B11: Input | C11: Debit udara | D11: Qa_Lmin | E11: L/min | F11: 71 | G11: =airlift_model__2[[#This Row],[Nilai_atau_Formula_Excel]]*(G7/F7)^2 -> 17.193899 | H11: =airlift_model__2[[#This Row],[Nilai_atau_Formula_Excel]]*(H7/$F7)^2 -> 9.6371191 | I11: =airlift_model__2[[#This Row],[Nilai_atau_Formula_Excel]]*(I7/$F7)^2 -> 6.1677562 | J11: =airlift_model__2[[#This Row],[Nilai_atau_Formula_Excel]]*(J7/$F7)^2 -> 3.1468144 | K11: =(G7/F7)^2 -> 0.24216759 | L11: Data Wurts-Parker
A12: 10 | B12: Input | C12: Debit air | D12: Qw_Lmin | E12: L/min | F12: 73.9 | G12: =airlift_model__2[[#This Row],[Nilai_atau_Formula_Excel]]*(G7/F7)^2 -> 17.896185 | H12: =airlift_model__2[[#This Row],[Nilai_atau_Formula_Excel]]*(H7/$F7)^2 -> 10.030748 | I12: =airlift_model__2[[#This Row],[Nilai_atau_Formula_Excel]]*(I7/$F7)^2 -> 6.4196787 | J12: =airlift_model__2[[#This Row],[Nilai_atau_Formula_Excel]]*(J7/$F7)^2 -> 3.2753463 | L12: Data Wurts-Parker
A13: 11 | B13: Konversi | C13: Debit udara | D13: Qa | E13: m3/s | F13: =F11/1000/60 -> 0.0011833333 | G13: =G11/1000/60 -> 0.00028656498 | H13: =H11/1000/60 -> 0.00016061865 | I13: =I11/1000/60 -> 0.00010279594 | J13: =J11/1000/60 -> 5.2446907e-05 | K13: Qa_Lmin/1000/60 | L13: Konversi L/min ke m3/s
A14: 12 | B14: Konversi | C14: Debit air | D14: Qw | E14: m3/s | F14: =F12/1000/60 -> 0.0012316667 | G14: =G12/1000/60 -> 0.00029826975 | H14: =H12/1000/60 -> 0.00016717913 | I14: =I12/1000/60 -> 0.00010699464 | J14: =J12/1000/60 -> 5.4589104e-05 | K14: Qw_Lmin/1000/60 | L14: Konversi L/min ke m3/s
A15: 13 | B15: Konversi | C15: Debit udara | D15: Qa_m3h | E15: m3/jam | F15: =F11*0.06 -> 4.26 | G15: =G11*0.06 -> 1.0316339 | H15: =H11*0.06 -> 0.57822715 | I15: =I11*0.06 -> 0.37006537 | J15: =J11*0.06 -> 0.18880886 | K15: Qa_Lmin*0.06 | L15: Konversi ke m3/jam
A16: 14 | B16: Konversi | C16: Debit air | D16: Qw_m3h | E16: m3/jam | F16: =F12*0.06 -> 4.434 | G16: =G12*0.06 -> 1.0737711 | H16: =H12*0.06 -> 0.60184488 | I16: =I12*0.06 -> 0.38518072 | J16: =J12*0.06 -> 0.19652078 | K16: Qw_Lmin*0.06 | L16: Konversi ke m3/jam
A17: 15 | B17: Perhitungan | C17: Debit campuran | D17: Qm_Lmin | E17: L/min | F17: =F11+F12 -> 144.9 | G17: =G11+G12 -> 35.090084 | H17: =H11+H12 -> 19.667867 | I17: =I11+I12 -> 12.587435 | J17: =J11+J12 -> 6.4221607 | K17: Qa+Qw | L17: Debit campuran dalam L/min
A18: 16 | B18: Perhitungan | C18: Debit campuran | D18: Qm | E18: m3/s | F18: =F13+F14 -> 0.002415 | G18: =G13+G14 -> 0.00058483473 | H18: =H13+H14 -> 0.00032779778 | I18: =I13+I14 -> 0.00020979058 | J18: =J13+J14 -> 0.00010703601 | K18: Qa+Qw | L18: Debit campuran dalam m3/s
A19: 17 | B19: Perhitungan | C19: Debit campuran | D19: Qm_m3h | E19: m3/jam | F19: =F15+F16 -> 8.694 | G19: =G15+G16 -> 2.105405 | H19: =H15+H16 -> 1.180072 | I19: =I15+I16 -> 0.75524609 | J19: =J15+J16 -> 0.38532964 | K19: Qa+Qw | L19: Debit campuran dalam m3/jam
A20: 18 | B20: Perhitungan | C20: Rasio air terhadap udara | D20: R_w_a | E20: - | F20: =F12/F11 -> 1.0408451 | G20: =G12/G11 -> 1.0408451 | H20: =H12/H11 -> 1.0408451 | I20: =I12/I11 -> 1.0408451 | J20: =J12/J11 -> 1.0408451 | K20: Qw/Qa | L20: Rasio data eksperimen
A21: 19 | B21: Perhitungan | C21: Luas penampang tube | D21: A_tube | E21: m2 | F21: =PI()*F7^2/4 -> 0.0045364598 | G21: =PI()*G7^2/4 -> 0.0010985835 | H21: =PI()*H7^2/4 -> 0.00061575216 | I21: =PI()*I7^2/4 -> 0.00039408138 | J21: =PI()*J7^2/4 -> 0.00020106193 | K21: pi*D^2/4 | L21: Luas lift tube
A22: 20 | B22: Perhitungan | C22: Void fraction homogen | D22: alpha | E22: - | F22: =F13/F18 -> 0.4899931 | G22: =G13/G18 -> 0.4899931 | H22: =H13/H18 -> 0.4899931 | I22: =I13/I18 -> 0.4899931 | J22: =J13/J18 -> 0.4899931 | K22: Qa/(Qa+Qw) | L22: Model no-slip
A23: 21 | B23: Input | C23: Densitas air | D23: rho_w | E23: kg/m3 | F23: 1000 | G23: 1000 | H23: 1000 | I23: 1000 | J23: 1000 | L23: Densitas air tawar
A24: 22 | B24: Input | C24: Densitas udara | D24: rho_a | E24: kg/m3 | F24: 1.2 | G24: 1.2 | H24: 1.2 | I24: 1.2 | J24: 1.2 | L24: Densitas udara
A25: 23 | B25: Perhitungan | C25: Densitas campuran | D25: rho_m | E25: kg/m3 | F25: =(1-F22)*F23+F22*F24 -> 510.59489 | G25: =(1-G22)*G23+G22*G24 -> 510.59489 | H25: =(1-H22)*H23+H22*H24 -> 510.59489 | I25: =(1-I22)*I23+I22*I24 -> 510.59489 | J25: =(1-J22)*J23+J22*J24 -> 510.59489 | K25: (1-alpha)*rho_w+alpha*rho_a | L25: Densitas campuran homogen
A26: 24 | B26: Input | C26: Viskositas air | D26: mu_w | E26: Pa.s | F26: 0.001 | G26: 0.001 | H26: 0.001 | I26: 0.001 | J26: 0.001 | L26: Viskositas air
A27: 25 | B27: Input | C27: Gravitasi | D27: g | E27: m/s2 | F27: 9.8 | G27: 9.8 | H27: 9.8 | I27: 9.8 | J27: 9.8 | L27: Konstanta gravitasi
A28: 26 | B28: Perhitungan | C28: Kecepatan air ekuivalen | D28: v_w | E28: m/s | F28: =F14/F21 -> 0.27150393 | G28: =G14/G21 -> 0.27150393 | H28: =H14/H21 -> 0.27150393 | I28: =I14/I21 -> 0.27150393 | J28: =J14/J21 -> 0.27150393 | K28: Qw/A | L28: Kecepatan air saja
A29: 27 | B29: Perhitungan | C29: Kecepatan campuran | D29: v_m | E29: m/s | F29: =F18/F21 -> 0.53235345 | G29: =G18/G21 -> 0.53235345 | H29: =H18/H21 -> 0.53235345 | I29: =I18/I21 -> 0.53235345 | J29: =J18/J21 -> 0.53235345 | K29: Qm/A | L29: Kecepatan campuran/discharge terendam
A30: 28 | B30: Perhitungan | C30: Reynolds air | D30: Re_w | E30: - | F30: =F23*F28*F7/F26 -> 20634.299 | G30: =G23*G28*G7/G26 -> 10154.247 | H30: =H23*H28*H7/H26 -> 7602.1101 | I30: =I23*I28*I7/I26 -> 6081.6881 | J30: =J23*J28*J7/J26 -> 4344.0629 | K30: rho*v*D/mu | L30: Reynolds berbasis air
A31: 29 | B31: Perhitungan | C31: Reynolds campuran | D31: Re_m | E31: - | F31: =F25*F29*F7/F26 -> 20658.088 | G31: =G25*G29*G7/G26 -> 10165.954 | H31: =H25*H29*H7/H26 -> 7610.8746 | I31: =I25*I29*I7/I26 -> 6088.6997 | J31: =J25*J29*J7/J26 -> 4349.0712 | K31: rho_m*v_m*D/mu | L31: Estimasi homogen
A32: 30 | B32: Input | C32: Darcy friction factor | D32: f | E32: - | F32: 0.026 | G32: 0.026 | H32: 0.026 | I32: 0.026 | J32: 0.026 | L32: Asumsi PVC turbulen ringan
A33: 31 | B33: Perhitungan | C33: Friction head campuran | D33: hf_mix | E33: m | F33: =F32*(F8/F7)*(F29^2/(2*F27)) -> 0.0049465662 | G33: =G32*(G8/G7)*(G29^2/(2*G27)) -> 0.010051846 | H33: =H32*(H8/H7)*(H29^2/(2*H27)) -> 0.013426394 | I33: =I32*(I8/I7)*(I29^2/(2*I27)) -> 0.016782992 | J33: =J32*(J8/J7)*(J29^2/(2*J27)) -> 0.023496189 | K33: f*(L/D)*(v^2/2g) | L33: Head loss berbasis fluida campuran
A34: 32 | B34: Perhitungan | C34: Friction pressure drop | D34: dP_f | E34: Pa | F34: =F25*F27*F33 -> 24.751776 | G34: =G25*G27*G33 -> 50.297727 | H34: =H25*H27*H33 -> 67.183392 | I34: =I25*I27*I33 -> 83.97924 | J34: =J25*J27*J33 -> 117.57094 | K34: rho_m*g*hf | L34: Friction pressure drop
A35: 33 | B35: Perhitungan | C35: Friction pressure drop | D35: dP_f_mmH2O | E35: mmH2O | F35: =F34/F27 -> 2.5256914 | G35: =G34/G27 -> 5.1324211 | H35: =H34/H27 -> 6.8554481 | I35: =I34/I27 -> 8.5693102 | J35: =J34/J27 -> 11.997034 | K35: dP/g | L35: Pressure-equivalent mmH2O
A36: 34 | B36: Input | C36: K elbow 90 derajat | D36: K_elbow | E36: - | F36: 0.75 | G36: 0.75 | H36: 0.75 | I36: 0.75 | J36: 0.75 | L36: Koefisien minor loss elbow
A37: 35 | B37: Input | C37: K outlet | D37: K_outlet | E37: - | F37: 1 | G37: 1 | H37: 1 | I37: 1 | J37: 1 | L37: Koefisien outlet terendam
A38: 36 | B38: Perhitungan | C38: Elbow head campuran | D38: h_elbow_mix | E38: m | F38: =F36*(F29^2/(2*F27)) -> 0.010844395 | G38: =G36*(G29^2/(2*G27)) -> 0.010844395 | H38: =H36*(H29^2/(2*H27)) -> 0.010844395 | I38: =I36*(I29^2/(2*I27)) -> 0.010844395 | J38: =J36*(J29^2/(2*J27)) -> 0.010844395 | K38: K*v^2/2g | L38: Head loss elbow
A39: 37 | B39: Perhitungan | C39: Elbow pressure drop | D39: dP_elbow | E39: Pa | F39: =F25*F27*F38 -> 54.263509 | G39: =G25*G27*G38 -> 54.263509 | H39: =H25*H27*H38 -> 54.263509 | I39: =I25*I27*I38 -> 54.263509 | J39: =J25*J27*J38 -> 54.263509 | K39: rho_m*g*h | L39: Pressure drop elbow
A40: 38 | B40: Perhitungan | C40: Elbow pressure drop | D40: dP_elbow_mmH2O | E40: mmH2O | F40: =F39/F27 -> 5.5370927 | G40: =G39/G27 -> 5.5370927 | H40: =H39/H27 -> 5.5370927 | I40: =I39/I27 -> 5.5370927 | J40: =J39/J27 -> 5.5370927 | K40: dP/g | L40: Pressure-equivalent mmH2O
...
