Workbook

Sheet INPUT
A1: Parameter | B1: Nilai | C1: Satuan | D1: Keterangan
A2: Bentuk kolam | B2: Bundar | C2: Bundar/Persegi | D2: Isi Bundar atau Persegi
A3: Diameter kolam | B3: 3 | C3: m | D3: Untuk kolam bundar
A4: Panjang kolam | B4: 0 | C4: m | D4: Untuk kolam persegi
A5: Lebar kolam | B5: 0 | C5: m | D5: Untuk kolam persegi
A6: Tinggi air | B6: 1 | C6: m | D6: Tinggi efektif air
A7: Volume air | B7: =IF(B2="Bundar",PI()*(B3/2)^2*B6,B4*B5*B6) -> 7.0685835 | C7: m3 | D7: Volume otomatis
A8: Dosis garam | B8: 1 | C8: kg/m3 | D8: Dosis persiapan
A9: Dosis molase | B9: 100 | C9: mL/m3 | D9: Dosis persiapan
A10: Dosis probiotik serbuk | B10: 10 | C10: g/m3 | D10: Dosis persiapan
A11: Dosis probiotik cair | B11: 30 | C11: mL/m3 | D11: Dosis persiapan
A12: Dosis dolomit | B12: 50 | C12: g/m3 | D12: Dosis persiapan
A13: Debit aerasi persiapan | B13: 30 | C13: L/menit/m3 | D13: Dosis persiapan
A14: Daya aerasi persiapan | B14: 10 | C14: W/m3 | D14: Dosis persiapan
A15: Waktu pematangan | B15: 7 | C15: hari | D15: Conditioning media
A16: BJ molase | B16: 1.35 | C16: g/mL | D16: Berat jenis molase
A17: Fraksi C molase | B17: 0.35 | C17: desimal | D17: Karbon molase
A18: OTE persiapan | B18: 0.06 | C18: desimal | D18: Efisiensi transfer oksigen
A19: Efektivitas dolomit/CCE | B19: 0.8 | C19: desimal | D19: Efektivitas CaCO3-equivalent
... A45: Volume flok | B45: 20 | C45: mL/L | D45: Hasil corong Imhoff

Sheet PERSIAPAN
A1: Parameter | B1: Formula | C1: Satuan | D1: Keterangan
A2: Volume air | B2: =INPUT!B7 -> 7.0685835 | C2: m3 | D2: Volume kolam
A3: Garam total | B3: =B2*INPUT!B8 -> 7.0685835 | C3: kg | D3: Kebutuhan garam
A4: Molase total | B4: =B2*INPUT!B9 -> 706.85835 | C4: mL | D4: Kebutuhan molase
A5: Probiotik serbuk total | B5: =B2*INPUT!B10 -> 70.685835 | C5: g | D5: Kebutuhan probiotik serbuk
A6: Probiotik cair total | B6: =B2*INPUT!B11 -> 212.0575 | C6: mL | D6: Kebutuhan probiotik cair
A7: Dolomit total | B7: =B2*INPUT!B12/1000 -> 0.35342917 | C7: kg | D7: Kebutuhan dolomit
A8: Debit aerasi total | B8: =B2*INPUT!B13 -> 212.0575 | C8: L/menit | D8: Kebutuhan debit udara
A9: Daya aerasi total | B9: =B2*INPUT!B14 -> 70.685835 | C9: watt | D9: Kebutuhan daya aerasi
A10: Energi aerasi 7 hari | B10: =B9/1000*24*INPUT!B15 -> 11.87522 | C10: kWh | D10: Energi persiapan
A11: Cl dari garam | B11: =INPUT!B8*1000*INPUT!B20*0.607 -> 576.65 | C11: mg/L Cl | D11: Ion klorida
A12: Na dari garam | B12: =INPUT!B8*1000*INPUT!B20*0.393 -> 373.35 | C12: mg/L Na | D12: Ion natrium
A13: Salinitas kasar | B13: =INPUT!B10*INPUT!B20 -> 9.5 | C13: ppt | D13: Estimasi salinitas
A14: Berat molase | B14: =B4*INPUT!B16 -> 954.25877 | C14: g | D14: Berat molase
A15: Karbon dari molase | B15: =B14*INPUT!B17 -> 333.99057 | C15: g C | D15: Karbon molase
A16: COD dari molase | B16: =B15*2.67 -> 891.75482 | C16: g COD | D16: Beban COD
A17: COD per m3 | B17: =B16/B2 -> 126.1575 | C17: g COD/m3 | D17: Setara mg/L
A18: Dolomit total gram | B18: =B2*INPUT!B12 -> 353.42917 | C18: g | D18: Dolomit total
A19: Potensi alkalinitas | B19: =INPUT!B12*INPUT!B19 -> 40 | C19: mg/L CaCO3 | D19: Potensi alkalinitas
A20: Ca potensial | B20: =INPUT!B12*0.217 -> 10.85 | C20: mg/L Ca | D20: Jika dolomit larut
A21: Mg potensial | B21: =INPUT!B12*0.132 -> 6.6 | C21: mg/L Mg | D21: Jika dolomit larut
A22: Debit udara total | B22: =B2*INPUT!B13 -> 212.0575 | C22: L/menit | D22: Debit aerasi
A23: OTR persiapan | B23: =B22*0.0179*INPUT!B18 -> 0.22774976 | C23: kg O2/jam | D23: Oksigen masuk
A24: OTR gram per jam | B24: =B23*1000 -> 227.74976 | C24: g O2/jam | D24: Oksigen masuk
A25: OTR per m3 | B25: =B24/B2 -> 32.22 | C25: g O2/jam/m3 | D25: Oksigen per volume
A26: DO persiapan | B26: 5.5 | C26: mg/L | D26: Input hasil ukur
A27: pH persiapan | B27: 7.2 | C27: pH | D27: Input hasil ukur
A28: Alkalinitas persiapan | B28: 100 | C28: mg/L CaCO3 | D28: Input hasil ukur
A29: TAN persiapan | B29: 0.5 | C29: mg/L TAN-N | D29: Input hasil ukur
A30: Nitrit persiapan | B30: 0.2 | C30: mg/L NO2-N | D30: Input hasil ukur
A31: Bau | B31: Tidak | C31: Ya/Tidak | D31: Input observasi
A32: Busa berlebihan | B32: Tidak | C32: Ya/Tidak | D32: Input observasi
A33: Status siap tebar | B33: =IF(AND(_xlfn.XLOOKUP("DO persiapan",A:A,B:B)>5,_xlfn.XLOOKUP("pH persiapan",A:A,B:B)>=6.8,_xlfn.XLOOKUP("pH persiapan",A:A,B:B)<=7.8,_xlfn.XLOOKUP("Alkalinitas persiapan",A:A,B:B)>=80,_xlfn.XLOOKUP("TAN persiapan",A:A,B:B)<=1,_xlfn.XLOOKUP("Nitrit persiapan",A:A,B:B)<=0.5,TRIM(_xlfn.XLOOKUP("Bau",A:A,B:B))="Tidak",TRIM(_xlfn.XLOOKUP("Busa berlebihan",A:A,B:B))="Tidak"),"SIAP TEBAR","BELUM SIAP") -> SIAP TEBAR | C33: Status | D33: Keputusan persiapan

Sheet OPERASI
A1: Parameter | B1: Formula | C1: Satuan | D1: Keterangan | E1: Column1
A2: Volume air | B2: =INPUT!B7 -> 7.0685835 | C2: m3 | D2: Volume kolam
A3: Biomassa ikan | B3: =INPUT!B21 -> 100 | C3: kg | D3: Biomassa operasi
A4: Feeding rate | B4: =INPUT!B22 -> 0.03 | C4: kg/kg/hari | D4: Persentase pakan
A5: Pakan harian | B5: =B3*B4 -> 3 | C5: kg/hari | D5: Pakan harian
A6: Pakan harian gram | B6: =B5*1000 -> 3000 | C6: g/hari | D6: Pakan harian
A7: N pakan | B7: =B6*INPUT!B23*0.16 -> 144 | C7: g N/hari | D7: Nitrogen pakan
A8: N limbah | B8: =B7*INPUT!B26 -> 108 | C8: g N/hari | D8: Nitrogen limbah
A9: TAN potensi per m3 | B9: =B8/B2 -> 15.278875 | C9: mg/L sebagai N | D9: Potensi harian
A10: C total pakan | B10: =B6*INPUT!B24 -> 1140 | C10: g C/hari | D10: Karbon total pakan
A11: C pakan tersedia | B11: =B10*INPUT!B25 -> 456 | C11: g C/hari | D11: Karbon tersedia mikroba
A12: Molase aktual | B12: =INPUT!B28 -> 0 | C12: mL/hari | D12: Molase operasi
A13: Berat molase aktual | B13: =B12*INPUT!B29 -> 0 | C13: g/hari | D13: Berat molase
A14: C molase aktual | B14: =B13*INPUT!B30 -> 0 | C14: g C/hari | D14: Karbon molase
A15: COD molase aktual | B15: =B14*2.67 -> 0 | C15: g COD/hari | D15: Beban COD
A16: Total C efektif | B16: =B11+B14 -> 456 | C16: g C/hari | D16: C pakan tersedia + C molase
A17: C/N efektif | B17: =IFERROR(B16/B8,0) -> 4.2222222 | C17: rasio | D17: C/N operasi
A18: Target C | B18: =B8*INPUT!B27 -> 1620 | C18: g C/hari | D18: Kebutuhan C target
A19: Defisit C | B19: =MAX(0,B18-B11) -> 1164 | C19: B26-B15) | D19: g C/hari | E19: Kekurangan C setelah pakan
A20: Molase teoritis dibutuhkan | B20: =B19/(INPUT!B29*INPUT!B30) -> 2463.4921 | C20: mL/hari | D20: Dosis teoritis
A21: Status C/N | B21: =IF(B17<12,"C/N RENDAH",IF(B17>20,"C/N TERLALU TINGGI","C/N AMAN")) -> C/N RENDAH | C21: Status | D21: Evaluasi C/N
A22: TAN terukur | B22: =INPUT!B31 -> 1 | C22: mg/L TAN-N | D22: Hasil ukur
A23: pH | B23: =INPUT!B32 -> 7.3 | C23: pH | D23: Hasil ukur
A24: Suhu | B24: =INPUT!B33 -> 28 | C24: C | D24: Hasil ukur
A25: pKa amonia | B25: =0.09018+2729.92/(273.15+B24) -> 9.1551642 | C25: pKa | D25: Hitung pKa
A26: Fraksi NH3 | B26: =1/(1+10^(B25-B23)) -> 0.013766249 | C26: desimal | D26: Fraksi NH3
A27: NH3-N bebas | B27: =B22*B26 -> 0.013766249 | C27: mg/L NH3-N | D27: Risiko toksik
A28: Status NH3 | B28: =IF(B27>=0.05,"BAHAYA NH3",IF(B27>=0.02,"WASPADA NH3","AMAN")) -> AMAN | C28: Status | D28: Evaluasi NH3
A29: Nitrit | B29: =INPUT!B34 -> 1 | C29: mg/L NO2-N | D29: Hasil ukur
A30: Cl awal | B30: =INPUT!B35 -> 50 | C30: mg/L | D30: Hasil ukur
A31: Faktor proteksi Cl | B31: 20 | C31: kali | D31: Target konservatif
A32: Cl target | B32: =B29*B31 -> 20 | C32: mg/L Cl | D32: Target klorida
A33: Defisit Cl | B33: =MAX(0,B32-B30) -> 0 | C33: B44-B42) | D33: mg/L Cl | E33: Kekurangan klorida
A34: NaCl dibutuhkan per m3 | B34: =B33/0.607 -> 0 | C34: g/m3 NaCl | D34: Kebutuhan garam
A35: NaCl total | B35: =B34*B2/1000 -> 0 | C35: kg NaCl total | D35: Kebutuhan garam total
A36: Status nitrit | B36: =IF(B29>=1,"WASPADA NITRIT",IF(B29>=0.5,"PERHATIAN","AMAN")) -> WASPADA NITRIT | C36: Status | D36: Evaluasi nitrit
A37: Alkalinitas terukur | B37: =INPUT!B36 -> 90 | C37: mg/L CaCO3 | D37: Hasil ukur
A38: Target alkalinitas | B38: =INPUT!B37 -> 120 | C38: mg/L CaCO3 | D38: Target
A39: Fraksi N nitrifikasi | B39: =INPUT!B38 -> 0.5 | C39: desimal | D39: Estimasi
A40: Efektivitas dolomit | B40: =INPUT!B19 -> 0.8 | C40: desimal | D40: CCE efektif
...

Sheet DASHBOARD
A1: Parameter | B1: Formula | C1: Satuan | D1: Keterangan
A2: Status DO | B2: =OPERASI!B61 -> AMAN | C2: Status | D2: Evaluasi DO
A3: Status C/N | B3: =OPERASI!B21 -> C/N RENDAH | C3: Status | D3: Evaluasi C/N
A4: Status NH3 | B4: =OPERASI!B28 -> AMAN | C4: Status | D4: Evaluasi NH3
A5: Status Nitrit | B5: =OPERASI!B36 -> WASPADA NITRIT | C5: Status | D5: Evaluasi nitrit
A6: Status Alkalinitas | B6: =OPERASI!B47 -> WASPADA | C6: Status | D6: Evaluasi alkalinitas
A7: Status Flok | B7: =OPERASI!B63 -> FLOK AMAN | C7: Status | D7: Evaluasi flok
A8: Status umum | B8: =IF(OR(B2="DARURAT",B4="BAHAYA NH3"),"DARURAT",IF(OR(B2="WASPADA",B3<>"C/N AMAN",B5<>"AMAN",B6<>"AMAN",B7="FLOK BERLEBIH"),"WASPADA","AMAN")) -> WASPADA | C8: Status | D8: Status umum kolam
A9: Rekomendasi DO | B9: =IF(OPERASI!B48<4,"DARURAT: tambah aerasi, hentikan molase, kurangi pakan",IF(OPERASI!B48<5,"WASPADA: tambah aerasi dan cek diffuser","DO aman")) -> DO aman | C9: Teks | D9: Tindakan DO
A10: Rekomendasi C/N | B10: =IF(OPERASI!B17<12,"C/N rendah: molase boleh dipertimbangkan jika DO aman",IF(OPERASI!B17>20,"C/N tinggi: hentikan molase dan cek busa/flok","C/N aman")) -> C/N rendah: molase boleh dipertimbangkan jika DO aman | C10: Teks | D10: Tindakan C/N
A11: Rekomendasi NH3 | B11: =IF(OPERASI!B27>=0.05,"Bahaya NH3: jangan naikkan pH, kurangi pakan, tambah aerasi",IF(OPERASI!B27>=0.02,"Waspada NH3: pantau pH dan TAN","NH3 aman")) -> NH3 aman | C11: Teks | D11: Tindakan NH3
A12: Rekomendasi Nitrit | B12: =IF(OPERASI!B29>=1,"Nitrit tinggi: cek Cl-, tambah garam sesuai hitungan",IF(OPERASI!B29>=0.5,"Nitrit mulai naik: tambah aerasi dan pantau Cl-","Nitrit aman")) -> Nitrit tinggi: cek Cl-, tambah garam sesuai hitungan | C12: Teks | D12: Tindakan nitrit
A13: Rekomendasi Alkalinitas | B13: =IF(OPERASI!B37<80,"Alkalinitas rendah: koreksi dolomit/NaHCO3 bertahap",IF(OPERASI!B37<100,"Waspada alkalinitas: pantau pH pagi","Alkalinitas aman")) -> Waspada alkalinitas: pantau pH pagi | C13: Teks | D13: Tindakan alkalinitas
A14: Rekomendasi Flok | B14: =IF(OPERASI!B62>50,"Flok berlebih: buang flok/lumpur, stop molase",IF(OPERASI!B62>30,"Flok tinggi: pantau DO dan TSS","Flok aman")) -> Flok aman | C14: Teks | D14: Tindakan flok
A15: Volume air | B15: =OPERASI!B2 -> 7.0685835 | C15: m3 | D15: Ringkasan
A16: Pakan harian | B16: =OPERASI!B5 -> 3 | C16: kg/hari | D16: Ringkasan
A17: N limbah harian | B17: =OPERASI!B8 -> 108 | C17: g N/hari | D17: Ringkasan
A18: C/N efektif | B18: =OPERASI!B17 -> 4.2222222 | C18: rasio | D18: Ringkasan
A19: Molase teoritis | B19: =OPERASI!B20 -> 2463.4921 | C19: mL/hari | D19: Ringkasan
A20: NH3-N bebas | B20: =OPERASI!B27 -> 0.013766249 | C20: mg/L | D20: Ringkasan
A21: Garam koreksi nitrit | B21: =OPERASI!B35 -> 0 | C21: kg | D21: Ringkasan
A22: Dolomit koreksi | B22: =OPERASI!B45 -> 0.26507188 | C22: kg | D22: Ringkasan
A23: OTR aerasi | B23: =OPERASI!B54 -> 0.3222 | C23: kg O2/jam | D23: Ringkasan
A24: OUR total | B24: =OPERASI!B56 -> 0.075 | C24: kg O2/jam | D24: Ringkasan
A25: Rasio OTR/OUR | B25: =OPERASI!B57 -> 4.296 | C25: rasio | D25: Ringkasan
A26: Perubahan DO per jam | B26: =OPERASI!B58 -> 34.971646 | C26: mg/L/jam | D26: Ringkasan

Sheet Sheet1
