Workbook

Sheet Model_Desain
A1: No | B1: Section | C1: Parameter | D1: Symbol | E1: Nilai | F1: Satuan | G1: Tipe | H1: Keterangan
B2: A. DATA KOLAM | C2: INPUT DATA KOLAM | G2: SECTION | H2: Ubah nilai INPUT sesuai kondisi kolam aktual.
A3: 1 | B3: A. DATA KOLAM | C3: Panjang kolam | D3: L_kolam | E3: 18 | F3: m | G3: INPUT | H3: Default artikel.
A4: 2 | B4: A. DATA KOLAM | C4: Lebar kolam | D4: W_kolam | E4: 3.5 | F4: m | G4: INPUT | H4: Default artikel.
A5: 3 | B5: A. DATA KOLAM | C5: Tinggi air kolam | D5: H_kolam | E5: 0.65 | F5: m | G5: INPUT | H5: Default artikel.
A6: 4 | B6: A. DATA KOLAM | C6: Luas permukaan kolam | D6: A_kolam | E6: =E3*E4 -> 63 | F6: m2 | G6: CALC | H6: A = L x W.
A7: 5 | B7: A. DATA KOLAM | C7: Volume air kolam | D7: V_kolam_m3 | E7: =E6*E5 -> 40.95 | F7: m3 | G7: CALC | H7: V = A x H.
A8: 6 | B8: A. DATA KOLAM | C8: Volume air kolam | D8: V_kolam_L | E8: =E7*1000 -> 40950 | F8: L | G8: CALC | H8: Konversi m3 ke liter.
B9: B. WASTE-BIOFLOC | C9: INPUT RASIO DAN DURASI WB | G9: SECTION | H9: Rasio ditulis sebagai desimal. 0.002 = 0.2%.
A10: 7 | B10: B. WASTE-BIOFLOC | C10: Rasio WB minimum konservatif | D10: R_WB_min | E10: 0.002 | F10: fraksi/hari | G10: INPUT | H10: Setara 0.2% volume kolam per hari.
A11: 8 | B11: B. WASTE-BIOFLOC | C11: Rasio WB nominal awal | D11: R_WB_nom | E11: 0.004 | F11: fraksi/hari | G11: INPUT | H11: Setara 0.4% volume kolam per hari.
A12: 9 | B12: B. WASTE-BIOFLOC | C12: Rasio WB desain normal | D12: R_WB_design | E12: 0.01 | F12: fraksi/hari | G12: INPUT | H12: Setara 1.0% volume kolam per hari.
A13: 10 | B13: B. WASTE-BIOFLOC | C13: Rasio WB high-floc sementara | D13: R_WB_max | E13: 0.02 | F13: fraksi/hari | G13: INPUT | H13: Setara 2.0% volume kolam per hari.
A14: 11 | B14: B. WASTE-BIOFLOC | C14: WB minimum konservatif | D14: V_WB_min | E14: =E8*E10 -> 81.9 | F14: L/hari | G14: CALC | H14: Volume WB 0.2%.
A15: 12 | B15: B. WASTE-BIOFLOC | C15: WB nominal awal | D15: V_WB_nom | E15: =E8*E11 -> 163.8 | F15: L/hari | G15: CALC | H15: Volume WB 0.4%.
A16: 13 | B16: B. WASTE-BIOFLOC | C16: WB desain normal | D16: V_WB_design | E16: =E8*E12 -> 409.5 | F16: L/hari | G16: CALC | H16: Volume WB 1.0%.
A17: 14 | B17: B. WASTE-BIOFLOC | C17: WB high-floc sementara | D17: V_WB_max | E17: =E8*E13 -> 819 | F17: L/hari | G17: CALC | H17: Volume WB 2.0%.
A18: 15 | B18: B. WASTE-BIOFLOC | C18: Durasi operasi batch | D18: t_batch | E18: 60 | F18: menit/hari | G18: INPUT | H18: Default artikel.
A19: 16 | B19: B. WASTE-BIOFLOC | C19: Debit WB minimum konservatif | D19: Q_WB_min | E19: =E14/E18 -> 1.365 | F19: L/menit | G19: CALC | H19: Debit jika batch 60 menit/hari.
A20: 17 | B20: B. WASTE-BIOFLOC | C20: Debit WB nominal awal | D20: Q_WB_nom | E20: =E15/E18 -> 2.73 | F20: L/menit | G20: CALC | H20: Debit jika batch 60 menit/hari.
A21: 18 | B21: B. WASTE-BIOFLOC | C21: Debit WB desain normal | D21: Q_WB_design | E21: =E16/E18 -> 6.825 | F21: L/menit | G21: CALC | H21: Debit operasi normal.
A22: 19 | B22: B. WASTE-BIOFLOC | C22: Debit WB high-floc sementara | D22: Q_WB_max | E22: =E17/E18 -> 13.65 | F22: L/menit | G22: CALC | H22: Debit high-floc sementara.
A23: 20 | B23: B. WASTE-BIOFLOC | C23: Debit WB high-floc | D23: Q_WB_max_m3s | E23: =E22/1000/60 -> 0.0002275 | F23: m3/s | G23: CALC | H23: Untuk cek kecepatan slot baffle.
B24: C. DIMENSI BASIN | C24: INPUT DIMENSI SEDIMENTATION BASIN | G24: SECTION | H24: Nilai default mengikuti artikel.
A25: 21 | B25: C. DIMENSI BASIN | C25: Panjang internal basin | D25: L_basin | E25: 1.75 | F25: m | G25: INPUT | H25: 175 cm.
A26: 22 | B26: C. DIMENSI BASIN | C26: Lebar internal basin | D26: W_basin | E26: 0.6 | F26: m | G26: INPUT | H26: 60 cm.
A27: 23 | B27: C. DIMENSI BASIN | C27: Tinggi air operasi basin | D27: H_air | E27: 0.65 | F27: m | G27: INPUT | H27: 65 cm.
A28: 24 | B28: C. DIMENSI BASIN | C28: Freeboard | D28: H_freeboard | E28: 0.2 | F28: m | G28: INPUT | H28: 20 cm.
A29: 25 | B29: C. DIMENSI BASIN | C29: Tinggi total dinding | D29: H_total | E29: =E27+E28 -> 0.85 | F29: m | G29: CALC | H29: H_total = H_air + freeboard.
A30: 26 | B30: C. DIMENSI BASIN | C30: Volume efektif basin | D30: V_basin_m3 | E30: =E25*E26*E27 -> 0.6825 | F30: m3 | G30: CALC | H30: V = L x W x H_air.
A31: 27 | B31: C. DIMENSI BASIN | C31: Volume efektif basin | D31: V_basin_L | E31: =E30*1000 -> 682.5 | F31: L | G31: CALC | H31: Konversi m3 ke liter.
A32: 28 | B32: C. DIMENSI BASIN | C32: Rasio panjang terhadap lebar | D32: L_W_ratio | E32: =E25/E26 -> 2.9166667 | F32: - | G32: CALC | H32: Target praktis sekitar 3:1.
B33: D. HRT BASIN | C33: CEK HYDRAULIC RETENTION TIME SEDIMENTATION BASIN | G33: SECTION | H33: HRT = V_basin / Q_WB.
A34: 29 | B34: D. HRT BASIN | C34: HRT operasi normal | D34: HRT_basin_normal | E34: =E31/E21 -> 100 | F34: menit | G34: CALC | H34: Menggunakan Q_WB_design.
A35: 30 | B35: D. HRT BASIN | C35: HRT high-floc sementara | D35: HRT_basin_high | E35: =E31/E22 -> 50 | F35: menit | G35: CALC | H35: Menggunakan Q_WB_max.
A36: 31 | B36: D. HRT BASIN | C36: HRT pada debit 5 L/menit | D36: HRT_5_Lpm | E36: =E31/5 -> 136.5 | F36: menit | G36: CALC | H36: Batas bawah operasi lapangan.
A37: 32 | B37: D. HRT BASIN | C37: HRT pada debit 10 L/menit | D37: HRT_10_Lpm | E37: =E31/10 -> 68.25 | F37: menit | G37: CALC | H37: Debit operasi normal menengah.
A38: 33 | B38: D. HRT BASIN | C38: HRT pada debit 15 L/menit | D38: HRT_15_Lpm | E38: =E31/15 -> 45.5 | F38: menit | G38: CALC | H38: Batas atas operasi lapangan.
B39: E. ZONA DAN PIPA | C39: INPUT ZONA, INLET, OUTLET, DAN DRAIN | G39: SECTION | H39: Semua panjang zona dalam cm.
A40: 34 | B40: E. ZONA DAN PIPA | C40: Ukuran PVC Inlet WB | D40: PVC_Inlet_WB | E40: 1 | F40: inch | G40: INPUT | H40: Default artikel.
...

Sheet Ringkasan
A1: Ringkasan Desain Mineralisasi LB → POC-B
A2: Item | B2: Nilai
A3: Feed LB normal | B3: =Model_Desain!E82 -> 409.5
A4: Feed LB high-floc | B4: =Model_Desain!E83 -> 819
A5: Buffer | B5: =Model_Desain!E88 -> 500
A6: CSTR | B6: =Model_Desain!E96 -> 1000
A7: MBBR | B7: =Model_Desain!E106 -> 750
A8: Media MBBR awal | B8: =Model_Desain!E111 -> 225
A9: Polishing | B9: =Model_Desain!E120 -> 250
A10: Storage POC-B minimum | B10: =Model_Desain!E129 -> 500
A11: Storage POC-B maksimum | B11: =Model_Desain!E130 -> 1000
A12: Total volume aktif | B12: =Model_Desain!E138 -> 2500
A13: HRT total normal | B13: =Model_Desain!E140 -> 6.1050061
A14: HRT total high-floc | B14: =Model_Desain!E141 -> 3.0525031
A15: DO CSTR min | B15: =Model_Desain!E99 -> 2
A16: DO CSTR max | B16: =Model_Desain!E100 -> 4
A17: DO MBBR min | B17: =Model_Desain!E113 -> 3
A18: DO MBBR max | B18: =Model_Desain!E114 -> 5
A20: Diffuser MBBR — airflow mixing reference | B20: =MBBR_Diffuser!E12 -> 26.25
A21: Diffuser MBBR — airflow kritis provisional | B21: =MBBR_Diffuser!E16 -> 26.25
A22: Diffuser MBBR — diameter lubang | B22: =MBBR_Diffuser!E22 -> 1
A23: Diffuser MBBR — ΔP orifice target | B23: =MBBR_Diffuser!E27 -> 0.5
A24: Diffuser MBBR — debit teoritis per lubang | B24: =MBBR_Diffuser!E30 -> 0.88422719
A25: Diffuser MBBR — reference grid | B25: 3 lateral × 10 lubang
A26: Diffuser MBBR — status | B26: =MBBR_Diffuser!E19 -> PROVISIONAL: BELUM ADA DATA OTR

Sheet Catatan
A1: Catatan Penggunaan Model
A2: 1. Ubah hanya baris dengan Tipe = INPUT pada sheet Model_Desain.
A3: 2. Bagian F sudah memakai revisi slot baffle: 10 slot @ 10 mm x 30 mm, A_open_total sekitar 0.0030 m2.
A4: 3. Bagian I sampai Q menambahkan desain mineralisasi LB menjadi POC-B: Buffer, CSTR, MBBR, Settling/Polishing, Storage.
A5: 4. Rumus HRT menggunakan satuan liter dan liter/hari sehingga hasil dalam hari; untuk sedimentation basin, HRT menggunakan liter dan liter/menit sehingga hasil dalam menit.
A6: 5. Model adalah desain awal dan harus divalidasi dengan pH, DO, bau, endapan, dan uji pengenceran tanaman.
A7: 6. Sheet MBBR_Diffuser berisi desain aerasi, orifice PVC Ø1,0 mm, reference configuration 3 lateral × 10 lubang, serta perhitungan blower dan wet test.
A8: 7. Sel berwarna kuning pada MBBR_Diffuser harus diisi dengan dimensi internal tangki, diameter dalam pipa, pressure loss perangkat, AOR, dan OTE aktual sebelum desain final.
A9: 8. Airflow 26,25 NL/min adalah reference mixing point; bukan spesifikasi blower final tanpa wet test carrier dan OTR.
A10: 9. Blower dipilih dari vendor curve pada debit dan tekanan kerja nyata, bukan dari free-air rating.

Sheet MBBR_Diffuser
A1: Desain Aerasi dan Diffuser MBBR — Reference Configuration & Wet Test
A2: Gunakan sel kuning sebagai INPUT. Konfigurasi 3 lateral × 10 lubang adalah reference wet test; jumlah lateral, ukuran pipa, blower, dan OTR final wajib dikunci dari dimensi tangki, wet test carrier, serta data LB aktual.
A4: No | B4: Section | C4: Parameter | D4: Symbol | E4: Nilai | F4: Satuan | G4: Tipe | H4: Keterangan | J4: Reference Grid A — 3 lateral × 10 lubang Ø1,0 mm (tidak berskala; wajib wet test)
B5: A. BASIS PROSES & CARRIER | C5: INPUT DAN BASIS PERHITUNGAN | G5: SECTION | H5: Nilai terkait MBBR terhubung ke sheet Model_Desain. | J5: Header udara dengan valve balancing pada masing-masing lateral. Lubang mengarah ke bawah / sedikit menyamping.
A6: 1 | B6: A. BASIS PROSES & CARRIER | C6: Volume MBBR | D6: V_MBBR | E6: =Model_Desain!E106 -> 750 | F6: L | G6: CALC | H6: Terhubung ke Model_Desain.
A7: 2 | B7: A. BASIS PROSES & CARRIER | C7: Media fill awal | D7: F_media_start | E7: =Model_Desain!E109 -> 0.3 | F7: fraksi | G7: CALC | H7: Terhubung ke Model_Desain. | K7: HEADER UDARA
A8: 3 | B8: A. BASIS PROSES & CARRIER | C8: Volume carrier awal | D8: V_carrier_start | E8: =Model_Desain!E111 -> 225 | F8: L | G8: CALC | H8: Terhubung ke Model_Desain.
A9: 4 | B9: A. BASIS PROSES & CARRIER | C9: Target DO MBBR minimum | D9: DO_MBBR_min | E9: =Model_Desain!E113 -> 3 | F9: mg/L | G9: CALC | H9: Terhubung ke Model_Desain. | J9: Lateral 1 | K9: ● | L9: ● | M9: ● | N9: ● | O9: ● | P9: ● | Q9: ● | R9: ● | S9: ● | T9: ● | U9: Flush
A10: 5 | B10: A. BASIS PROSES & CARRIER | C10: Target DO MBBR maksimum | D10: DO_MBBR_max | E10: =Model_Desain!E114 -> 5 | F10: mg/L | G10: CALC | H10: Terhubung ke Model_Desain.
A11: 6 | B11: A. BASIS PROSES & CARRIER | C11: Koefisien awal mixing carrier | D11: C_MIX | E11: 35 | F11: NL/min/m3 | G11: INPUT | H11: Reference wet test; bukan kapasitas final.
A12: 7 | B12: A. BASIS PROSES & CARRIER | C12: Airflow reference untuk carrier mixing | D12: Q_air_mixing_ref | E12: =E6/1000*E11 -> 26.25 | F12: NL/min | G12: CALC | H12: V_MBBR × C_MIX. | J12: Lateral 2 | K12: ● | L12: ● | M12: ● | N12: ● | O12: ● | P12: ● | Q12: ● | R12: ● | S12: ● | T12: ● | U12: Flush
A13: 8 | B13: A. BASIS PROSES & CARRIER | C13: AOR residual MBBR pada beban puncak | D13: AOR_peak | E13: 0 | F13: kg O2/jam | G13: INPUT | H13: Isi setelah uji OUR/OTR atau data proses tervalidasi.
A14: 9 | B14: A. BASIS PROSES & CARRIER | C14: OTE aktual grid PVC dalam LB | D14: OTE_actual | E14: 0 | F14: fraksi | G14: INPUT | H14: Jangan memakai OTE membrane diffuser tanpa uji aktual.
A15: 10 | B15: A. BASIS PROSES & CARRIER | C15: Airflow minimum berdasarkan OTR residual | D15: Q_air_OTR | E15: =IF(E13*E14>0,E13/(60*1.204*0.232*E14)*1000,0) -> 0 | F15: NL/min | G15: CALC | H15: 0 bila AOR atau OTE belum diisi. | J15: Lateral 3 | K15: ● | L15: ● | M15: ● | N15: ● | O15: ● | P15: ● | Q15: ● | R15: ● | S15: ● | T15: ● | U15: Flush
A16: 11 | B16: A. BASIS PROSES & CARRIER | C16: Airflow kritis provisional | D16: Q_air_critical | E16: =MAX(E12,E15) -> 26.25 | F16: NL/min | G16: CALC | H16: max(mixing reference, OTR residual).
A17: 12 | B17: A. BASIS PROSES & CARRIER | C17: Faktor availability / fouling | D17: F_availability | E17: 1 | F17: fraksi | G17: INPUT | H17: Default 1,00; tetapkan dari hasil wet test dan filosofi reliability. | J17: Bila Q_air_critical melebihi reference mixing point, evaluasi Config B (4 lateral × 9 lubang) atau redesign layout; jangan sekadar menaikkan pressure tanpa mengecek carrier movement dan OTR.
A18: 13 | B18: A. BASIS PROSES & CARRIER | C18: Airflow terpasang yang diperlukan | D18: Q_air_installed | E18: =E16*E17 -> 26.25 | F18: NL/min | G18: CALC | H18: Basis pemilihan blower setelah semua input divalidasi.
A19: 14 | B19: A. BASIS PROSES & CARRIER | C19: Status desain airflow | D19: Airflow_status | E19: =IF(E13*E14>0,"VERIFIKASI OTR + WET TEST","PROVISIONAL: BELUM ADA DATA OTR") -> PROVISIONAL: BELUM ADA DATA OTR | F19: - | G19: OUTPUT | H19: Harus tetap provisional hingga OTR dan wet test selesai.
B21: B. ORIFICE DIFFUSER PVC | C21: BASIS MEKANIK DIFFUSER | G21: SECTION | H21: Diameter lubang dan target ΔP awal.
A22: 15 | B22: B. ORIFICE DIFFUSER PVC | C22: Diameter lubang diffuser | D22: d_hole | E22: 1 | F22: mm | G22: INPUT | H22: Basis awal fabrikasi grid PVC.
A23: 16 | B23: B. ORIFICE DIFFUSER PVC | C23: Diameter lubang diffuser | D23: d_hole_m | E23: =E22/1000 -> 0.001 | F23: m | G23: CALC | H23: Konversi mm ke m.
A24: 17 | B24: B. ORIFICE DIFFUSER PVC | C24: Luas satu lubang | D24: A_hole | E24: =PI()*E23^2/4 -> 7.8539816e-07 | F24: m2 | G24: CALC | H24: A = πd²/4.
A25: 18 | B25: B. ORIFICE DIFFUSER PVC | C25: Koefisien discharge awal | D25: C_d_initial | E25: 0.65 | F25: - | G25: INPUT | H25: Wajib dikalibrasi terhadap lubang PVC aktual.
A26: 19 | B26: B. ORIFICE DIFFUSER PVC | C26: Densitas udara referensi | D26: rho_air | E26: 1.2 | F26: kg/m3 | G26: INPUT | H26: Reference simplifikasi untuk pemeriksaan awal.
A27: 20 | B27: B. ORIFICE DIFFUSER PVC | C27: Target pressure drop orifice | D27: dP_orifice_target | E27: 0.5 | F27: kPa | G27: INPUT | H27: Target awal untuk pemerataan distribusi udara.
A28: 21 | B28: B. ORIFICE DIFFUSER PVC | C28: Target pressure drop orifice | D28: dP_orifice_target_Pa | E28: =E27*1000 -> 500 | F28: Pa | G28: CALC | H28: Konversi kPa ke Pa.
A29: 22 | B29: B. ORIFICE DIFFUSER PVC | C29: Target pressure drop orifice | D29: dP_orifice_target_mmH2O | E29: =E28/9.80665 -> 50.985811 | F29: mmH2O | G29: CALC | H29: 1 mmH2O = 9,80665 Pa.
A30: 23 | B30: B. ORIFICE DIFFUSER PVC | C30: Debit teoritis per lubang | D30: q_hole_ref | E30: =E25*E24*SQRT(2*E28/E26)*60000 -> 0.88422719 | F30: L/min | G30: CALC | H30: q = Cd × A × √(2ΔP/ρ) × 60000.
A31: 24 | B31: B. ORIFICE DIFFUSER PVC | C31: Jumlah lubang minimum @ Q kritis | D31: N_hole_required | E31: =ROUNDUP(E16/E30,0) -> 30 | F31: lubang | G31: CALC | H31: Dibulatkan ke atas.
A32: 25 | B32: B. ORIFICE DIFFUSER PVC | C32: Jumlah lubang dipilih | D32: N_hole_selected | E32: 30 | F32: lubang | G32: INPUT | H32: Reference configuration 3 lateral × 10 lubang.
A33: 26 | B33: B. ORIFICE DIFFUSER PVC | C33: Debit aktual rata-rata per lubang | D33: q_hole_selected | E33: =E16/E32 -> 0.875 | F33: L/min | G33: CALC | H33: Q kritis / jumlah lubang dipilih.
A34: 27 | B34: B. ORIFICE DIFFUSER PVC | C34: Pressure drop aktual pada lubang | D34: dP_orifice_actual_Pa | E34: =E28*(E33/E30)^2 -> 489.61913 | F34: Pa | G34: CALC | H34: ΔP berbanding q².
A35: 28 | B35: B. ORIFICE DIFFUSER PVC | C35: Pressure drop aktual pada lubang | D35: dP_orifice_actual | E35: =E34/1000 -> 0.48961913 | F35: kPa | G35: CALC | H35: Konversi Pa ke kPa.
A36: 29 | B36: B. ORIFICE DIFFUSER PVC | C36: Pressure drop aktual pada lubang | D36: dP_orifice_actual_mmH2O | E36: =E34/9.80665 -> 49.927257 | F36: mmH2O | G36: CALC | H36: Konversi Pa ke mmH2O.
A37: 30 | B37: B. ORIFICE DIFFUSER PVC | C37: Status jumlah lubang | D37: N_hole_status | E37: =IF(E32>=E31,"CUKUP UNTUK Q KRITIS","TAMBAH LUBANG / REDESIGN") -> CUKUP UNTUK Q KRITIS | F37: - | G37: OUTPUT | H37: Wajib cukup untuk airflow kritis.
B39: C. REFERENCE CONFIGURATION | C39: KONFIGURASI WET TEST — BUKAN FINAL | G39: SECTION | H39: Pilih berdasarkan hasil carrier movement, DO, dan OTR.
A40: 31 | B40: C. REFERENCE CONFIGURATION | C40: Config A — airflow | D40: Q_config_A | E40: =E12 -> 26.25 | F40: NL/min | G40: CALC | H40: Reference mixing point.
A41: 32 | B41: C. REFERENCE CONFIGURATION | C41: Config A — jumlah lateral | D41: N_lateral_A | E41: 3 | F41: lateral | G41: INPUT | H41: Reference: 3 lateral.
A42: 33 | B42: C. REFERENCE CONFIGURATION | C42: Config A — lubang per lateral | D42: N_hole_lateral_A | E42: 10 | F42: lubang/lateral | G42: INPUT | H42: Reference: 10 lubang per lateral.
A43: 34 | B43: C. REFERENCE CONFIGURATION | C43: Config A — jumlah lubang total | D43: N_hole_A | E43: =E41*E42 -> 30 | F43: lubang | G43: CALC | H43: N lateral × lubang/lateral.
...
